Workbook

Sheet Como Usar Esta Planilha - Model
A1: COMO USAR ESTA PLANILHA-MODELO
A3: 1) Todo início de mês: duplique este arquivo inteiro e renomeie (ex: "CB_DIEESE_JULHO_2026").
A4: 2) Na aba "Calendário", ajuste a data inicial (célula F4) e preencha Pesquisador/Crítica de cada mercado. As datas e dias da semana das demais linhas se recalculam sozinhos.
A5: 3) Em cada aba "MERCADO X", a DATA, SEMANA, PESQUISADOR e CRÍTICA já vêm preenchidos automaticamente a partir da aba Calendário -- não precisa digitar de novo.
A6: 4) Preencha apenas a coluna PREÇO em cada aba de mercado e o horário. Se o preço coletado for 50% maior que a média do mesmo item no mês anterior, a célula fica destacada em vermelho automaticamente.
A7: 5) A aba "Resumos, Totais e Médias" mostra, produto por produto, o preço em cada um dos 40 mercados lado a lado, além da média, mínimo, máximo e quantidade coletada.
A8: 6) No fechamento do mês: copie a coluna PREÇO MÉDIO da aba "Resumos, Totais e Médias" e cole como VALORES na aba "Histórico - Média Mês Anterior", substituindo os valores antigos. Isso alimenta o alerta de preço do mês seguinte.
A10: Atenção: ao coletar o preço do pão, lembrem-se de registrar o valor correspondente a 1 kg de pão (aproximadamente 20 unidades), e não o preço de apenas uma unidade.
A11: Atenção: ao coletar o preço dos ovos, lembrem-se de registrar apenas o preço da unidade, e não o valor da cartela ou de outra quantidade.
A12: Atenção: ao coletar os preços no site Preço da Hora, verifique se há um valor em vermelho, com números menores, acima do preço em negrito e com números maiores. Registre apenas o preço em vermelho, pois ele corresponde ao preço sem promoção. O valor em negrito representa o preço promocional e, portanto, não deve ser utilizado na coleta.
A13: Atenção: ao coletar no preço da hora, o final da página pode pode conter um botão com a frase "mais resultados". Esse botão pode ser apertado somente três vezes consecutivas, depois o preço da hora dá erro. Depois de fazer "mais resultados" por três vezes, se ainda obtiver esse botão, vá ao item organizador da página e troque menor preço por maior preço e assim consiga mais três páginas.
A14: Atenção: ao preencher a planilha não faça uso de ctrl c, ctrl v. Pois a planilha possui formatações, formulas e layout que podem ser alteradas com essa prática.

Sheet Calendário
C2: ="CALENDÁRIO COLETA CESTA BÁSICA DE "&CHOOSE(MONTH(G4),"JANEIRO","FEVEREIRO","MARÇO","ABRIL","MAIO","JUNHO","JULHO","AGOSTO","SETEMBRO","OUTUBRO","NOVEMBRO","DEZEMBRO")&" DE "&YEAR(G4) -> CALENDÁRIO COLETA CESTA BÁSICA DE SETEMBRO DE 2026
A3: Código Estabelecimento | C3: Estabelecimentos | D3: Bairros | E3: Semana | F3: Dias da Semana | G3: Data | H3: Data Efetiva | I3: Pesquisador | J3: Crítica | K3: Prints | L3: Registros
A4: M1 | B4: Verificar | C4: Atakarejo | D4: Candeias | E4: =1+INT((NETWORKDAYS($G$4,H4)-1)/5) -> 2 | F4: =CHOOSE(WEEKDAY(H4,2),"Segunda-Feira","Terça-Feira","Quarta-Feira","Quinta-Feira","Sexta-Feira","Sábado","Domingo") -> Segunda-Feira | G4: 46272 | H4: 46279 | I4: Mécia | J4: Mateus | K4: Carlos Eduardo | L4: {=INDIRECT("'M1'!E108")} -> 40
A5: M2 | B5: E1.25 | C5: Supermercado São Jorge | D5: Henriqueta Prates | E5: =1+INT((NETWORKDAYS($G$4,H5)-1)/5) -> 2 | F5: =CHOOSE(WEEKDAY(H5,2),"Segunda-Feira","Terça-Feira","Quarta-Feira","Quinta-Feira","Sexta-Feira","Sábado","Domingo") -> Segunda-Feira | G5: =G4 -> 46272 | H5: 46279 | I5: Mécia | J5: Mateus | L5: {=INDIRECT("'M2'!E108")} -> 0
A6: M3 | B6: Verificar | C6: Economart | D6: Bateias | E6: =1+INT((NETWORKDAYS($G$4,H6)-1)/5) -> 1 | F6: =CHOOSE(WEEKDAY(H6,2),"Segunda-Feira","Terça-Feira","Quarta-Feira","Quinta-Feira","Sexta-Feira","Sábado","Domingo") -> Terça-Feira | G6: =G5+1 -> 46273 | H6: =G6 -> 46273 | I6: Darci | J6: Carlos Eduardo | K6: Mateus | L6: {=INDIRECT("'M3'!E108")} -> 44
A7: M4 | B7: E3.04 | C7: Mercadinho Deus Dará | D7: Alto Maron | E7: =1+INT((NETWORKDAYS($G$4,H7)-1)/5) -> 1 | F7: =CHOOSE(WEEKDAY(H7,2),"Segunda-Feira","Terça-Feira","Quarta-Feira","Quinta-Feira","Sexta-Feira","Sábado","Domingo") -> Terça-Feira | G7: =G6 -> 46273 | H7: =G7 -> 46273 | I7: Darci | J7: Carlos Eduardo | L7: {=INDIRECT("'M4'!E108")} -> 6
A8: M5 | B8: Verificar | C8: Mix Mateus | D8: Boa Vista | E8: =1+INT((NETWORKDAYS($G$4,H8)-1)/5) -> 1 | F8: =CHOOSE(WEEKDAY(H8,2),"Segunda-Feira","Terça-Feira","Quarta-Feira","Quinta-Feira","Sexta-Feira","Sábado","Domingo") -> Quarta-Feira | G8: =G7+1 -> 46274 | H8: =G8 -> 46274 | I8: Carlos Eduardo | J8: Igor | K8: Verônica | L8: {=INDIRECT("'M5'!E108")} -> 38
A9: M6 | B9: Verificar | C9: Mercado Eliene | D9: Ibirapuera | E9: =1+INT((NETWORKDAYS($G$4,H9)-1)/5) -> 1 | F9: =CHOOSE(WEEKDAY(H9,2),"Segunda-Feira","Terça-Feira","Quarta-Feira","Quinta-Feira","Sexta-Feira","Sábado","Domingo") -> Quarta-Feira | G9: =G8 -> 46274 | H9: =G9 -> 46274 | I9: Carlos Eduardo | J9: Igor | L9: {=INDIRECT("'M6'!E108")} -> 2
A10: M7 | B10: Verificar | C10: Santo Antônio Supermercados | D10: Candeias | E10: =1+INT((NETWORKDAYS($G$4,H10)-1)/5) -> 1 | F10: =CHOOSE(WEEKDAY(H10,2),"Segunda-Feira","Terça-Feira","Quarta-Feira","Quinta-Feira","Sexta-Feira","Sábado","Domingo") -> Quinta-Feira | G10: =G9+1 -> 46275 | H10: =G10 -> 46275 | I10: Igor | J10: Mécia | K10: Darci | L10: {=INDIRECT("'M7'!E108")} -> 48
A11: M8 | B11: E3.05 | C11: Mercado Teixeira | D11: Brasil | E11: =1+INT((NETWORKDAYS($G$4,H11)-1)/5) -> 1 | F11: =CHOOSE(WEEKDAY(H11,2),"Segunda-Feira","Terça-Feira","Quarta-Feira","Quinta-Feira","Sexta-Feira","Sábado","Domingo") -> Quinta-Feira | G11: =G10 -> 46275 | H11: =G11 -> 46275 | I11: Igor | J11: Mécia | L11: {=INDIRECT("'M8'!E108")} -> 12
A12: M9 | B12: E1.15 | C12: Supermercado Modelo | D12: Alto Maron | E12: =1+INT((NETWORKDAYS($G$4,H12)-1)/5) -> 1 | F12: =CHOOSE(WEEKDAY(H12,2),"Segunda-Feira","Terça-Feira","Quarta-Feira","Quinta-Feira","Sexta-Feira","Sábado","Domingo") -> Sexta-Feira | G12: =G11+1 -> 46276 | H12: =G12 -> 46276 | I12: Mateus | J12: Darci | K12: Mécia | L12: {=INDIRECT("'M9'!E108")} -> 0
A13: M10 | B13: E1.10 | C13: Supermercado Esplendor | D13: Boa Vista | E13: =1+INT((NETWORKDAYS($G$4,H13)-1)/5) -> 1 | F13: =CHOOSE(WEEKDAY(H13,2),"Segunda-Feira","Terça-Feira","Quarta-Feira","Quinta-Feira","Sexta-Feira","Sábado","Domingo") -> Sexta-Feira | G13: =G12 -> 46276 | H13: =G13 -> 46276 | I13: Mateus | J13: Darci | L13: {=INDIRECT("'M10'!E108")} -> 0
A14: M11 | B14: E2.01 | C14: Sendas Distribuidora S/A (Assaí Atacadista) | D14: Felícia | E14: =1+INT((NETWORKDAYS($G$4,H14)-1)/5) -> 2 | F14: =CHOOSE(WEEKDAY(H14,2),"Segunda-Feira","Terça-Feira","Quarta-Feira","Quinta-Feira","Sexta-Feira","Sábado","Domingo") -> Segunda-Feira | G14: =G13+3 -> 46279 | H14: 46279 | I14: Mécia | J14: Mateus | K14: Carlos Eduardo | L14: {=INDIRECT("'M11'!E108")} -> 0
A15: M12 | B15: E1.22 | C15: Supermercado Sampaio | D15: Guarani | E15: =1+INT((NETWORKDAYS($G$4,H15)-1)/5) -> 2 | F15: =CHOOSE(WEEKDAY(H15,2),"Segunda-Feira","Terça-Feira","Quarta-Feira","Quinta-Feira","Sexta-Feira","Sábado","Domingo") -> Segunda-Feira | G15: =G14 -> 46279 | H15: 46279 | I15: Mécia | J15: Mateus | L15: {=INDIRECT("'M12'!E108")} -> 0
A16: M13 | B16: Verificar | C16: Atacadão (Brumado) | D16: Bateias | E16: =1+INT((NETWORKDAYS($G$4,H16)-1)/5) -> 2 | F16: =CHOOSE(WEEKDAY(H16,2),"Segunda-Feira","Terça-Feira","Quarta-Feira","Quinta-Feira","Sexta-Feira","Sábado","Domingo") -> Terça-Feira | G16: =G15+1 -> 46280 | H16: =G16 -> 46280 | I16: Darci | J16: Carlos Eduardo | K16: Mateus | L16: {=INDIRECT("'M13'!E108")} -> 31
A17: M14 | B17: Verificar | C17: Supermercado Central Ipanema | D17: Boa Vista | E17: =1+INT((NETWORKDAYS($G$4,H17)-1)/5) -> 2 | F17: =CHOOSE(WEEKDAY(H17,2),"Segunda-Feira","Terça-Feira","Quarta-Feira","Quinta-Feira","Sexta-Feira","Sábado","Domingo") -> Terça-Feira | G17: =G16 -> 46280 | H17: =G17 -> 46280 | I17: Darci | J17: Carlos Eduardo | L17: {=INDIRECT("'M14'!E108")} -> 10
A18: M15 | B18: Verificar | C18: Supermercados BH (Juracy) | D18: Boa Vista | E18: =1+INT((NETWORKDAYS($G$4,H18)-1)/5) -> 2 | F18: =CHOOSE(WEEKDAY(H18,2),"Segunda-Feira","Terça-Feira","Quarta-Feira","Quinta-Feira","Sexta-Feira","Sábado","Domingo") -> Quarta-Feira | G18: =G17+1 -> 46281 | H18: =G18 -> 46281 | I18: Carlos Eduardo | J18: Igor | K18: Verônica | L18: {=INDIRECT("'M15'!E108")} -> 0
A19: M16 | B19: E1.08 | C19: Supermercado Canaã | D19: Campinhos | E19: =1+INT((NETWORKDAYS($G$4,H19)-1)/5) -> 2 | F19: =CHOOSE(WEEKDAY(H19,2),"Segunda-Feira","Terça-Feira","Quarta-Feira","Quinta-Feira","Sexta-Feira","Sábado","Domingo") -> Quarta-Feira | G19: =G18 -> 46281 | H19: =G19 -> 46281 | I19: Carlos Eduardo | J19: Igor | L19: {=INDIRECT("'M16'!E108")} -> 0
A20: M17 | B20: E1.06 | C20: Supermercado Aliança | D20: Patagônia | E20: =1+INT((NETWORKDAYS($G$4,H20)-1)/5) -> 2 | F20: =CHOOSE(WEEKDAY(H20,2),"Segunda-Feira","Terça-Feira","Quarta-Feira","Quinta-Feira","Sexta-Feira","Sábado","Domingo") -> Quinta-Feira | G20: =G19+1 -> 46282 | H20: =G20 -> 46282 | I20: Igor | J20: Mécia | K20: Darci | L20: {=INDIRECT("'M17'!E108")} -> 0
A21: M18 | B21: Verificar | C21: Pereira Atacado e Varejo (Boa Vista) | D21: Boa Vista | E21: =1+INT((NETWORKDAYS($G$4,H21)-1)/5) -> 2 | F21: =CHOOSE(WEEKDAY(H21,2),"Segunda-Feira","Terça-Feira","Quarta-Feira","Quinta-Feira","Sexta-Feira","Sábado","Domingo") -> Quinta-Feira | G21: =G20 -> 46282 | H21: =G21 -> 46282 | I21: Igor | J21: Mécia | L21: {=INDIRECT("'M18'!E108")} -> 0
A22: M19 | B22: E1.24 | C22: Andralmeida LTDA (São Geraldo) | D22: Alto Maron | E22: =1+INT((NETWORKDAYS($G$4,H22)-1)/5) -> 2 | F22: =CHOOSE(WEEKDAY(H22,2),"Segunda-Feira","Terça-Feira","Quarta-Feira","Quinta-Feira","Sexta-Feira","Sábado","Domingo") -> Sexta-Feira | G22: =G21+1 -> 46283 | H22: =G22 -> 46283 | I22: Mateus | J22: Darci | K22: Mécia | L22: {=INDIRECT("'M19'!E108")} -> 0
A23: M20 | B23: Verificar | C23: São Miguel Supermercado | D23: Espírito Santo | E23: =1+INT((NETWORKDAYS($G$4,H23)-1)/5) -> 2 | F23: =CHOOSE(WEEKDAY(H23,2),"Segunda-Feira","Terça-Feira","Quarta-Feira","Quinta-Feira","Sexta-Feira","Sábado","Domingo") -> Sexta-Feira | G23: =G22 -> 46283 | H23: =G23 -> 46283 | I23: Mateus | J23: Darci | L23: {=INDIRECT("'M20'!E108")} -> 0
A24: M21 | B24: Verificar | C24: Supermercados BH (Rosa Cruz) | D24: Candeias | E24: =1+INT((NETWORKDAYS($G$4,H24)-1)/5) -> 3 | F24: =CHOOSE(WEEKDAY(H24,2),"Segunda-Feira","Terça-Feira","Quarta-Feira","Quinta-Feira","Sexta-Feira","Sábado","Domingo") -> Segunda-Feira | G24: =G23+3 -> 46286 | H24: =G24 -> 46286 | I24: Mécia | J24: Mateus | K24: Carlos Eduardo | L24: {=INDIRECT("'M21'!E108")} -> 0
A25: M22 | B25: E1.03 | C25: Supermercados N U (Bairro Brasil) | D25: Brasil | E25: =1+INT((NETWORKDAYS($G$4,H25)-1)/5) -> 3 | F25: =CHOOSE(WEEKDAY(H25,2),"Segunda-Feira","Terça-Feira","Quarta-Feira","Quinta-Feira","Sexta-Feira","Sábado","Domingo") -> Segunda-Feira | G25: =G24 -> 46286 | H25: =G25 -> 46286 | I25: Mécia | J25: Mateus | L25: {=INDIRECT("'M22'!E108")} -> 0
A26: M23 | B26: E2.02 | C26: Atacadão (Pres. Dutra) | D26: Felícia | E26: =1+INT((NETWORKDAYS($G$4,H26)-1)/5) -> 3 | F26: =CHOOSE(WEEKDAY(H26,2),"Segunda-Feira","Terça-Feira","Quarta-Feira","Quinta-Feira","Sexta-Feira","Sábado","Domingo") -> Terça-Feira | G26: =G25+1 -> 46287 | H26: =G26 -> 46287 | I26: Darci | J26: Carlos Eduardo | K26: Mateus | L26: {=INDIRECT("'M23'!E108")} -> 0
A27: M24 | B27: Verificar | C27: Supermercado São João | D27: Guarani | E27: =1+INT((NETWORKDAYS($G$4,H27)-1)/5) -> 3 | F27: =CHOOSE(WEEKDAY(H27,2),"Segunda-Feira","Terça-Feira","Quarta-Feira","Quinta-Feira","Sexta-Feira","Sábado","Domingo") -> Terça-Feira | G27: =G26 -> 46287 | H27: =G27 -> 46287 | I27: Darci | J27: Carlos Eduardo | L27: {=INDIRECT("'M24'!E108")} -> 0
A28: M25 | B28: E1.11 | C28: G Barbosa Supermercado | D28: Candeias | E28: =1+INT((NETWORKDAYS($G$4,H28)-1)/5) -> 3 | F28: =CHOOSE(WEEKDAY(H28,2),"Segunda-Feira","Terça-Feira","Quarta-Feira","Quinta-Feira","Sexta-Feira","Sábado","Domingo") -> Quarta-Feira | G28: =G27+1 -> 46288 | H28: =G28 -> 46288 | I28: Carlos Eduardo | J28: Igor | K28: Verônica | L28: {=INDIRECT("'M25'!E108")} -> 0
A29: M26 | B29: Verificar | C29: Pereira Atacado e Varejo (Alto Maron) | D29: Alto Maron | E29: =1+INT((NETWORKDAYS($G$4,H29)-1)/5) -> 3 | F29: =CHOOSE(WEEKDAY(H29,2),"Segunda-Feira","Terça-Feira","Quarta-Feira","Quinta-Feira","Sexta-Feira","Sábado","Domingo") -> Quarta-Feira | G29: =G28 -> 46288 | H29: =G29 -> 46288 | I29: Carlos Eduardo | J29: Igor | L29: {=INDIRECT("'M26'!E108")} -> 0
A30: M27 | B30: Verificar | C30: Supermercados BH (Brumado) | D30: Ibirapuera | E30: =1+INT((NETWORKDAYS($G$4,H30)-1)/5) -> 3 | F30: =CHOOSE(WEEKDAY(H30,2),"Segunda-Feira","Terça-Feira","Quarta-Feira","Quinta-Feira","Sexta-Feira","Sábado","Domingo") -> Quinta-Feira | G30: =G29+1 -> 46289 | H30: =G30 -> 46289 | I30: Igor | J30: Mécia | K30: Darci | L30: {=INDIRECT("'M27'!E108")} -> 0
A31: M28 | B31: Verificar | C31: Super Mix Supermercado | D31: Boa Vista | E31: =1+INT((NETWORKDAYS($G$4,H31)-1)/5) -> 3 | F31: =CHOOSE(WEEKDAY(H31,2),"Segunda-Feira","Terça-Feira","Quarta-Feira","Quinta-Feira","Sexta-Feira","Sábado","Domingo") -> Quinta-Feira | G31: =G30 -> 46289 | H31: =G31 -> 46289 | I31: Igor | J31: Mécia | L31: {=INDIRECT("'M28'!E108")} -> 0
A32: M29 | B32: Verificar | C32: Gbom Supermercado | D32: Ibirapuera | E32: =1+INT((NETWORKDAYS($G$4,H32)-1)/5) -> 3 | F32: =CHOOSE(WEEKDAY(H32,2),"Segunda-Feira","Terça-Feira","Quarta-Feira","Quinta-Feira","Sexta-Feira","Sábado","Domingo") -> Sexta-Feira | G32: =G31+1 -> 46290 | H32: =G32 -> 46290 | I32: Mateus | J32: Darci | K32: Mécia | L32: {=INDIRECT("'M29'!E108")} -> 0
A33: M30 | B33: E1.07 | C33: Supermercado Azevedo | D33: Urbis VI | E33: =1+INT((NETWORKDAYS($G$4,H33)-1)/5) -> 3 | F33: =CHOOSE(WEEKDAY(H33,2),"Segunda-Feira","Terça-Feira","Quarta-Feira","Quinta-Feira","Sexta-Feira","Sábado","Domingo") -> Sexta-Feira | G33: =G32 -> 46290 | H33: =G33 -> 46290 | I33: Mateus | J33: Darci | L33: {=INDIRECT("'M30'!E108")} -> 0
A34: M31 | B34: E1.12 | C34: Supermercado Jurema | D34: Jurema | E34: =1+INT((NETWORKDAYS($G$4,H34)-1)/5) -> 4 | F34: =CHOOSE(WEEKDAY(H34,2),"Segunda-Feira","Terça-Feira","Quarta-Feira","Quinta-Feira","Sexta-Feira","Sábado","Domingo") -> Segunda-Feira | G34: =G33+3 -> 46293 | H34: =G34 -> 46293 | I34: Mécia | J34: Mateus | K34: Carlos Eduardo | L34: {=INDIRECT("'M31'!E108")} -> 0
A35: M32 | B35: E4.03 | C35: Supermercado Petybom | D35: Primavera | E35: =1+INT((NETWORKDAYS($G$4,H35)-1)/5) -> 4 | F35: =CHOOSE(WEEKDAY(H35,2),"Segunda-Feira","Terça-Feira","Quarta-Feira","Quinta-Feira","Sexta-Feira","Sábado","Domingo") -> Segunda-Feira | G35: =G34 -> 46293 | H35: =G35 -> 46293 | I35: Mécia | J35: Mateus | L35: {=INDIRECT("'M32'!E108")} -> 0
A36: M33 | B36: E1.20 | C36: Supermercados Petrópolis | D36: Cruzeiro | E36: =1+INT((NETWORKDAYS($G$4,H36)-1)/5) -> 4 | F36: =CHOOSE(WEEKDAY(H36,2),"Segunda-Feira","Terça-Feira","Quarta-Feira","Quinta-Feira","Sexta-Feira","Sábado","Domingo") -> Terça-Feira | G36: =G35+1 -> 46294 | H36: =G36 -> 46294 | I36: Darci | J36: Carlos Eduardo | K36: Mateus | L36: {=INDIRECT("'M33'!E108")} -> 0
A37: M34 | B37: Verificar | C37: Supermercados N U (Boulevard) | D37: Candeias | E37: =1+INT((NETWORKDAYS($G$4,H37)-1)/5) -> 4 | F37: =CHOOSE(WEEKDAY(H37,2),"Segunda-Feira","Terça-Feira","Quarta-Feira","Quinta-Feira","Sexta-Feira","Sábado","Domingo") -> Terça-Feira | G37: =G36 -> 46294 | H37: =G37 -> 46294 | I37: Darci | J37: Carlos Eduardo | L37: {=INDIRECT("'M34'!E108")} -> 0
A38: M35 | B38: E1.14 | C38: Supermercado Local | D38: Vila Serrana | E38: =1+INT((NETWORKDAYS($G$4,H38)-1)/5) -> 4 | F38: =CHOOSE(WEEKDAY(H38,2),"Segunda-Feira","Terça-Feira","Quarta-Feira","Quinta-Feira","Sexta-Feira","Sábado","Domingo") -> Quarta-Feira | G38: =G37+1 -> 46295 | H38: =G38 -> 46295 | I38: Carlos Eduardo | J38: Igor | K38: Verônica | L38: {=INDIRECT("'M35'!E108")} -> 0
A39: M36 | B39: E1.21 | C39: Rondelli Comércio e transporte LTDA | D39: Candeias | E39: =1+INT((NETWORKDAYS($G$4,H39)-1)/5) -> 4 | F39: =CHOOSE(WEEKDAY(H39,2),"Segunda-Feira","Terça-Feira","Quarta-Feira","Quinta-Feira","Sexta-Feira","Sábado","Domingo") -> Quarta-Feira | G39: =G38 -> 46295 | H39: =G39 -> 46295 | I39: Carlos Eduardo | J39: Igor | L39: {=INDIRECT("'M36'!E108")} -> 0
A40: M37 | B40: E1.17 | C40: NS Aparecida | D40: Brasil | E40: =1+INT((NETWORKDAYS($G$4,H40)-1)/5) -> 3 | F40: =CHOOSE(WEEKDAY(H40,2),"Segunda-Feira","Terça-Feira","Quarta-Feira","Quinta-Feira","Sexta-Feira","Sábado","Domingo") -> Quinta-Feira | G40: =G39+1 -> 46296 | H40: 46289 | I40: Igor | J40: Mécia | K40: Darci | L40: {=INDIRECT("'M37'!E108")} -> 0
A41: M38 | B41: Verificar | C41: Supermercado Família | D41: Felícia | E41: =1+INT((NETWORKDAYS($G$4,H41)-1)/5) -> 3 | F41: =CHOOSE(WEEKDAY(H41,2),"Segunda-Feira","Terça-Feira","Quarta-Feira","Quinta-Feira","Sexta-Feira","Sábado","Domingo") -> Quinta-Feira | G41: =G40 -> 46296 | H41: 46289 | I41: Igor | J41: Mécia | L41: {=INDIRECT("'M38'!E108")} -> 0
...

Sheet Histórico - Média Mês Anterior
A1: INSTRUÇÕES: no fim de cada mês, copie a coluna PREÇO MÉDIO da aba "Resumos, Totais e Médias" e cole AQUI como VALORES (Ctrl+Shift+V > Colar valores) antes de iniciar a coleta do mês seguinte.
A3: ITEM/PRODUTO | B3: CÓDIGO DO PRODUTO | C3: MARCAS DO PRODUTO | D3: CÓD. BARRAS PdH | E3: PREÇO
A4: Açúcar 1.1.05
A5: Açucar (1Kg) | E5: 3.6068519
B6: 1.1.05.01 | C6: Açucar Cristal Vida 1Kg | D6: 7898920795044 | E6: 3.6889474
B7: 1.1.05.01 | C7: Açucar Cristal Coceal 1Kg | D7: 7898292530038 | E7: 3.9092308
B8: 1.1.05.01 | C8: Açúcar Cristal Vale Bahia 1Kg | D8: 7898968872011 | E8: 3.6466667
B9: 1.1.05.01 | C9: Açucar Cristal Dona Mira 1Kg | D9: 7898964714070 | E9: 3.0866667
B10: 1.1.05.01 | C10: Açucar Cristal Baiano 1Kg | D10: 7898920795259 | E10: 3.2171429
A11: Arroz 1.2.03
A12: Arroz Parboilizado (1Kg) | E12: 4.7923729
B13: 1.2.03.01 | C13: Arroz Parboilizado Urbano 1Kg | D13: 7896038306053 | E13: 4.9895652
B14: 1.2.03.01 | C14: Arroz Parboilizado Tio João 1Kg | D14: 7893500018469 | E14: 5.0316667
B15: 1.2.03.01 | C15: Arroz Parboilizado Fazenda 1Kg | D15: 7896389600107 | E15: 4.085
B16: 1.2.03.01 | C16: Arroz Parboilizado Tia Maria 1Kg | D16: 609963230297 | E16: 4.1333333
B17: 1.2.03.01 | C17: Arroz Parboilizado Camil 1Kg | D17: 7896006716112 | E17: 5.013
A18: Frutas 1.3.02 | E18: 6.6884615
B19: 1.3.02.01 | C19: Banana da Prata (1 Kg) | D19: BANANA PRATA | E19: 5.6996429
B20: 1.3.02.02 | C20: Maça Nacional Vermelha (1 Kg) | D20: MAÇA NACIONAL | E20: 9.2054545
A21: Café 1.1.03
A22: Café (250g)
B23: 1.1.03.01 | C23: Café Torrado e Moído Tradicional 250g Bahia a Vácuo | D23: 7898017920199
B24: 1.1.03.01 | C24: Café Torrado e Moído Tradicional 250g Pilão a Vácuo | D24: 7896089012637
B25: 1.1.03.01 | C25: Café Torrado e Moído Tradicional 250g 3 Corações a Vácuo | D25: 7896005800362
B26: 1.1.03.01 | C26: Café Torrado e Moído Tradicional 250g Mellita a Vácuo | D26: 7891021006071
B27: 1.1.03.01 | C27: Café Torrado e Moído Tradicional 250g Maratá a Vácuo | D27: 7898286200039
A28: Carnes, ovos e embutidos 1.2.01
B29: 1.2.01.01 | C29: Carne Acém (1 kg) | D29: CARNE ACÉM | E29: 34.600909
B30: 1.2.01.02 | C30: Carne Alcatra (1 kg) | D30: CARNE ALCATRA | E30: 48.078889
B31: 1.2.01.03 | C31: Charque - Dianteira ou Ponta de Agulha (1Kg) | D31: CHARQUE
B32: 1.2.01.04 | C32: Frango Inteiro Congelado (1 kg) | D32: FRANGO INTEIRO | E32: 10.903
B33: 1.2.01.06 | C33: Ovos Brancos (Unid.) | D33: OVOS BRANCOS | E33: 2.5111111
A34: Linguiça Calabresa (400g) | E34: 15.277091
B35: 1.2.01.05 | C35: Linguiça Calabresa 400g Sadia | D35: 7891515620981 | E35: 13.804286
B36: 1.2.01.05 | C36: Linguiça Calabresa 400g Perdigao | D36: 7891515977511 | E36: 15.394706
B37: 1.2.01.05 | C37: Linguiça Calabresa 400g Seara | D37: 7894904009862 | E37: 15.526111
B38: 1.2.01.05 | C38: Linguiça Calabresa 400g Pamplona | D38: 7896716301271 | E38: 16.98
B39: 1.2.01.05 | C39: Linguiça Calabresa 400g Aurora | D39: 7891164005832 | E39: 17.96
A40: Farinhas e Massas 1.1.02
A41: Farinha de Mandioca (1Kg) | E41: 6.7670588
...

Sheet M1
A2: QUESTIONÁRIO DE COLETA DE PREÇOS
A3: DATA: | B3: =IFERROR(Calendário!H4,"") -> 46279 | C3: ESTABELECIMENTO: | D3: =Calendário!C4 -> Atakarejo
A4: SEMANA: | B4: =IFERROR(Calendário!E4,"") -> 2 | C4: PESQUISADOR: | D4: =IFERROR(IF(Calendário!I4=0,"",Calendário!I4),"") -> Mécia
A5: HORA: | C5: CRÍTICA: | D5: =IFERROR(IF(Calendário!J4=0,"",Calendário!J4),"") -> Mateus
A7: ITEM/PRODUTO | B7: CÓDIGO DO PRODUTO | C7: MARCAS DO PRODUTO | D7: CÓD. BARRAS PdH | E7: PREÇO
A8: Açúcar 1.1.05
A9: Açucar (1Kg)
B10: 1.1.05.01 | C10: Açucar Cristal Vida 1Kg | D10: 7898920795044 | E10: 3.19
B11: 1.1.05.01 | C11: Açucar Cristal Coceal 1Kg | D11: 7898292530038 | E11: x
B12: 1.1.05.01 | C12: Açúcar Cristal Vale Bahia 1Kg | D12: 7898968872011 | E12: x
B13: 1.1.05.01 | C13: Açucar Cristal Dona Mira 1Kg | D13: 7898964714070 | E13: x
B14: 1.1.05.01 | C14: Açucar Cristal Baiano 1Kg | D14: 7898920795259 | E14: 3.06
A15: Arroz 1.2.03
A16: Arroz Parboilizado (1Kg)
B17: 1.2.03.01 | C17: Arroz Parboilizado Urbano 1Kg | D17: 7896038306053 | E17: x
B18: 1.2.03.01 | C18: Arroz Parboilizado Tio João 1Kg | D18: 7893500018469 | E18: 4.98
B19: 1.2.03.01 | C19: Arroz Parboilizado Fazenda 1Kg | D19: 7896389600107 | E19: x
B20: 1.2.03.01 | C20: Arroz Parboilizado Tia Maria 1Kg | D20: 609963230297 | E20: x
B21: 1.2.03.01 | C21: Arroz Parboilizado Camil 1Kg | D21: 7896006716112 | E21: 4.88
A22: Frutas 1.3.02
B23: 1.3.02.01 | C23: Banana da Prata (1 Kg) | D23: BANANA PRATA | E23: 5.69
B24: 1.3.02.02 | C24: Maça Nacional Vermelha (1 Kg) | D24: MAÇA NACIONAL | E24: x
A25: Café 1.1.03
A26: Café (250g)
B27: 1.1.03.01 | C27: Café Torrado e Moído Tradicional 250g Bahia a Vácuo | D27: 7898017920199 | E27: 11.48
B28: 1.1.03.01 | C28: Café Torrado e Moído Tradicional 250g Pilão a Vácuo | D28: 7896089012637 | E28: 14.79
B29: 1.1.03.01 | C29: Café Torrado e Moído Tradicional 250g 3 Corações a Vácuo | D29: 7896005800362 | E29: 12.98
B30: 1.1.03.01 | C30: Café Torrado e Moído Tradicional 250g Mellita a Vácuo | D30: 7891021006071 | E30: 11.79
B31: 1.1.03.01 | C31: Café Torrado e Moído Tradicional 250g Maratá a Vácuo | D31: 7898286200039 | E31: 14.09
A32: Carnes, ovos e embutidos 1.2.01
B33: 1.2.01.01 | C33: Carne Acém (1 kg) | D33: CARNE ACÉM | E33: 27.8
B34: 1.2.01.02 | C34: Carne Alcatra (1 kg) | D34: CARNE ALCATRA | E34: 47.48
B35: 1.2.01.03 | C35: Charque - Dianteira ou Ponta de Agulha (1Kg) | D35: CHARQUE | E35: 40.98
B36: 1.2.01.04 | C36: Frango Inteiro Congelado (1 kg) | D36: FRANGO INTEIRO | E36: x
B37: 1.2.01.06 | C37: Ovos Brancos (Unid.) | D37: OVOS BRANCOS | E37: x
A38: Linguiça Calabresa (400g)
B39: 1.2.01.05 | C39: Linguiça Calabresa 400g Sadia | D39: 7891515620981 | E39: 13.78
B40: 1.2.01.05 | C40: Linguiça Calabresa 400g Perdigao | D40: 7891515977511 | E40: 15.06
B41: 1.2.01.05 | C41: Linguiça Calabresa 400g Seara | D41: 7894904009862 | E41: 14.99
B42: 1.2.01.05 | C42: Linguiça Calabresa 400g Pamplona | D42: 7896716301271 | E42: x
...

Sheet M2
A2: QUESTIONÁRIO DE COLETA DE PREÇOS
A3: DATA: | B3: =IFERROR(Calendário!H5,"") -> 46279 | C3: ESTABELECIMENTO: | D3: =Calendário!C5 -> Supermercado São Jorge
A4: SEMANA: | B4: =IFERROR(Calendário!E5,"") -> 2 | C4: PESQUISADOR: | D4: =IFERROR(IF(Calendário!I5=0,"",Calendário!I5),"") -> Mécia
A5: HORA: | C5: CRÍTICA: | D5: =IFERROR(IF(Calendário!J5=0,"",Calendário!J5),"") -> Mateus
A7: ITEM/PRODUTO | B7: CÓDIGO DO PRODUTO | C7: MARCAS DO PRODUTO | D7: CÓD. BARRAS PdH | E7: PREÇO
A8: Açúcar 1.1.05
A9: Açucar (1Kg)
B10: 1.1.05.01 | C10: Açucar Cristal Vida 1Kg | D10: 7898920795044 | E10: x
B11: 1.1.05.01 | C11: Açucar Cristal Coceal 1Kg | D11: 7898292530038 | E11: x
B12: 1.1.05.01 | C12: Açúcar Cristal Vale Bahia 1Kg | D12: 7898968872011
B13: 1.1.05.01 | C13: Açucar Cristal Dona Mira 1Kg | D13: 7898964714070
B14: 1.1.05.01 | C14: Açucar Cristal Baiano 1Kg | D14: 7898920795259
A15: Arroz 1.2.03
A16: Arroz Parboilizado (1Kg)
B17: 1.2.03.01 | C17: Arroz Parboilizado Urbano 1Kg | D17: 7896038306053
B18: 1.2.03.01 | C18: Arroz Parboilizado Tio João 1Kg | D18: 7893500018469
B19: 1.2.03.01 | C19: Arroz Parboilizado Fazenda 1Kg | D19: 7896389600107
B20: 1.2.03.01 | C20: Arroz Parboilizado Tia Maria 1Kg | D20: 609963230297
B21: 1.2.03.01 | C21: Arroz Parboilizado Camil 1Kg | D21: 7896006716112
A22: Frutas 1.3.02
B23: 1.3.02.01 | C23: Banana da Prata (1 Kg) | D23: BANANA PRATA
B24: 1.3.02.02 | C24: Maça Nacional Vermelha (1 Kg) | D24: MAÇA NACIONAL
A25: Café 1.1.03
A26: Café (250g)
B27: 1.1.03.01 | C27: Café Torrado e Moído Tradicional 250g Bahia a Vácuo | D27: 7898017920199
B28: 1.1.03.01 | C28: Café Torrado e Moído Tradicional 250g Pilão a Vácuo | D28: 7896089012637
B29: 1.1.03.01 | C29: Café Torrado e Moído Tradicional 250g 3 Corações a Vácuo | D29: 7896005800362
B30: 1.1.03.01 | C30: Café Torrado e Moído Tradicional 250g Mellita a Vácuo | D30: 7891021006071
B31: 1.1.03.01 | C31: Café Torrado e Moído Tradicional 250g Maratá a Vácuo | D31: 7898286200039
A32: Carnes, ovos e embutidos 1.2.01
B33: 1.2.01.01 | C33: Carne Acém (1 kg) | D33: CARNE ACÉM
B34: 1.2.01.02 | C34: Carne Alcatra (1 kg) | D34: CARNE ALCATRA
B35: 1.2.01.03 | C35: Charque - Dianteira ou Ponta de Agulha (1Kg) | D35: CHARQUE
B36: 1.2.01.04 | C36: Frango Inteiro Congelado (1 kg) | D36: FRANGO INTEIRO
B37: 1.2.01.06 | C37: Ovos Brancos (Unid.) | D37: OVOS BRANCOS
A38: Linguiça Calabresa (400g)
B39: 1.2.01.05 | C39: Linguiça Calabresa 400g Sadia | D39: 7891515620981
B40: 1.2.01.05 | C40: Linguiça Calabresa 400g Perdigao | D40: 7891515977511
B41: 1.2.01.05 | C41: Linguiça Calabresa 400g Seara | D41: 7894904009862
B42: 1.2.01.05 | C42: Linguiça Calabresa 400g Pamplona | D42: 7896716301271
...

Sheet M3
A2: QUESTIONÁRIO DE COLETA DE PREÇOS
A3: DATA: | B3: =IFERROR(Calendário!H6,"") -> 46273 | C3: ESTABELECIMENTO: | D3: =Calendário!C6 -> Economart
A4: SEMANA: | B4: =IFERROR(Calendário!E6,"") -> 1 | C4: PESQUISADOR: | D4: =IFERROR(IF(Calendário!I6=0,"",Calendário!I6),"") -> Darci
A5: HORA: | B5: 0.42777778 | C5: CRÍTICA: | D5: =IFERROR(IF(Calendário!J6=0,"",Calendário!J6),"") -> Carlos Eduardo
A7: ITEM/PRODUTO | B7: CÓDIGO DO PRODUTO | C7: MARCAS DO PRODUTO | D7: CÓD. BARRAS PdH | E7: PREÇO
A8: Açúcar 1.1.05
A9: Açucar (1Kg)
B10: 1.1.05.01 | C10: Açucar Cristal Vida 1Kg | D10: 7898920795044 | E10: 3.29
B11: 1.1.05.01 | C11: Açucar Cristal Coceal 1Kg | D11: 7898292530038 | E11: x
B12: 1.1.05.01 | C12: Açúcar Cristal Vale Bahia 1Kg | D12: 7898968872011 | E12: x
B13: 1.1.05.01 | C13: Açucar Cristal Dona Mira 1Kg | D13: 7898964714070 | E13: x
B14: 1.1.05.01 | C14: Açucar Cristal Baiano 1Kg | D14: 7898920795259 | E14: 3.19
A15: Arroz 1.2.03
A16: Arroz Parboilizado (1Kg)
B17: 1.2.03.01 | C17: Arroz Parboilizado Urbano 1Kg | D17: 7896038306053 | E17: 4.18
B18: 1.2.03.01 | C18: Arroz Parboilizado Tio João 1Kg | D18: 7893500018469 | E18: 5.19
B19: 1.2.03.01 | C19: Arroz Parboilizado Fazenda 1Kg | D19: 7896389600107 | E19: x
B20: 1.2.03.01 | C20: Arroz Parboilizado Tia Maria 1Kg | D20: 609963230297 | E20: x
B21: 1.2.03.01 | C21: Arroz Parboilizado Camil 1Kg | D21: 7896006716112 | E21: 5.29
A22: Frutas 1.3.02
B23: 1.3.02.01 | C23: Banana da Prata (1 Kg) | D23: BANANA PRATA | E23: 3.99
B24: 1.3.02.02 | C24: Maça Nacional Vermelha (1 Kg) | D24: MAÇA NACIONAL | E24: x
A25: Café 1.1.03
A26: Café (250g)
B27: 1.1.03.01 | C27: Café Torrado e Moído Tradicional 250g Bahia a Vácuo | D27: 7898017920199 | E27: 11.49
B28: 1.1.03.01 | C28: Café Torrado e Moído Tradicional 250g Pilão a Vácuo | D28: 7896089012637 | E28: 15.49
B29: 1.1.03.01 | C29: Café Torrado e Moído Tradicional 250g 3 Corações a Vácuo | D29: 7896005800362 | E29: 14.99
B30: 1.1.03.01 | C30: Café Torrado e Moído Tradicional 250g Mellita a Vácuo | D30: 7891021006071 | E30: 11.99
B31: 1.1.03.01 | C31: Café Torrado e Moído Tradicional 250g Maratá a Vácuo | D31: 7898286200039 | E31: 15.29
A32: Carnes, ovos e embutidos 1.2.01
B33: 1.2.01.01 | C33: Carne Acém (1 kg) | D33: CARNE ACÉM | E33: x
B34: 1.2.01.02 | C34: Carne Alcatra (1 kg) | D34: CARNE ALCATRA | E34: x
B35: 1.2.01.03 | C35: Charque - Dianteira ou Ponta de Agulha (1Kg) | D35: CHARQUE | E35: 39.9
B36: 1.2.01.04 | C36: Frango Inteiro Congelado (1 kg) | D36: FRANGO INTEIRO | E36: x
B37: 1.2.01.06 | C37: Ovos Brancos (Unid.) | D37: OVOS BRANCOS | E37: x
A38: Linguiça Calabresa (400g)
B39: 1.2.01.05 | C39: Linguiça Calabresa 400g Sadia | D39: 7891515620981 | E39: 15.49
B40: 1.2.01.05 | C40: Linguiça Calabresa 400g Perdigao | D40: 7891515977511 | E40: 16.98
B41: 1.2.01.05 | C41: Linguiça Calabresa 400g Seara | D41: 7894904009862 | E41: 17.98
B42: 1.2.01.05 | C42: Linguiça Calabresa 400g Pamplona | D42: 7896716301271 | E42: x
...

Sheet M4
A2: QUESTIONÁRIO DE COLETA DE PREÇOS
A3: DATA: | B3: =IFERROR(Calendário!H7,"") -> 46273 | C3: ESTABELECIMENTO: | D3: =Calendário!C7 -> Mercadinho Deus Dará
A4: SEMANA: | B4: =IFERROR(Calendário!E7,"") -> 1 | C4: PESQUISADOR: | D4: =IFERROR(IF(Calendário!I7=0,"",Calendário!I7),"") -> Darci
A5: HORA: | B5: 0.42916667 | C5: CRÍTICA: | D5: =IFERROR(IF(Calendário!J7=0,"",Calendário!J7),"") -> Carlos Eduardo
A7: ITEM/PRODUTO | B7: CÓDIGO DO PRODUTO | C7: MARCAS DO PRODUTO | D7: CÓD. BARRAS PdH | E7: PREÇO
A8: Açúcar 1.1.05
A9: Açucar (1Kg)
B10: 1.1.05.01 | C10: Açucar Cristal Vida 1Kg | D10: 7898920795044 | E10: 3.39
B11: 1.1.05.01 | C11: Açucar Cristal Coceal 1Kg | D11: 7898292530038 | E11: x
B12: 1.1.05.01 | C12: Açúcar Cristal Vale Bahia 1Kg | D12: 7898968872011 | E12: x
B13: 1.1.05.01 | C13: Açucar Cristal Dona Mira 1Kg | D13: 7898964714070 | E13: x
B14: 1.1.05.01 | C14: Açucar Cristal Baiano 1Kg | D14: 7898920795259 | E14: x
A15: Arroz 1.2.03
A16: Arroz Parboilizado (1Kg)
B17: 1.2.03.01 | C17: Arroz Parboilizado Urbano 1Kg | D17: 7896038306053 | E17: x
B18: 1.2.03.01 | C18: Arroz Parboilizado Tio João 1Kg | D18: 7893500018469 | E18: x
B19: 1.2.03.01 | C19: Arroz Parboilizado Fazenda 1Kg | D19: 7896389600107 | E19: x
B20: 1.2.03.01 | C20: Arroz Parboilizado Tia Maria 1Kg | D20: 609963230297 | E20: x
B21: 1.2.03.01 | C21: Arroz Parboilizado Camil 1Kg | D21: 7896006716112 | E21: x
A22: Frutas 1.3.02
B23: 1.3.02.01 | C23: Banana da Prata (1 Kg) | D23: BANANA PRATA | E23: x
B24: 1.3.02.02 | C24: Maça Nacional Vermelha (1 Kg) | D24: MAÇA NACIONAL | E24: x
A25: Café 1.1.03
A26: Café (250g)
B27: 1.1.03.01 | C27: Café Torrado e Moído Tradicional 250g Bahia a Vácuo | D27: 7898017920199 | E27: x
B28: 1.1.03.01 | C28: Café Torrado e Moído Tradicional 250g Pilão a Vácuo | D28: 7896089012637 | E28: x
B29: 1.1.03.01 | C29: Café Torrado e Moído Tradicional 250g 3 Corações a Vácuo | D29: 7896005800362 | E29: x
B30: 1.1.03.01 | C30: Café Torrado e Moído Tradicional 250g Mellita a Vácuo | D30: 7891021006071 | E30: x
B31: 1.1.03.01 | C31: Café Torrado e Moído Tradicional 250g Maratá a Vácuo | D31: 7898286200039 | E31: x
A32: Carnes, ovos e embutidos 1.2.01
B33: 1.2.01.01 | C33: Carne Acém (1 kg) | D33: CARNE ACÉM | E33: x
B34: 1.2.01.02 | C34: Carne Alcatra (1 kg) | D34: CARNE ALCATRA | E34: x
B35: 1.2.01.03 | C35: Charque - Dianteira ou Ponta de Agulha (1Kg) | D35: CHARQUE | E35: 67.99
B36: 1.2.01.04 | C36: Frango Inteiro Congelado (1 kg) | D36: FRANGO INTEIRO | E36: x
B37: 1.2.01.06 | C37: Ovos Brancos (Unid.) | D37: OVOS BRANCOS | E37: x
A38: Linguiça Calabresa (400g)
B39: 1.2.01.05 | C39: Linguiça Calabresa 400g Sadia | D39: 7891515620981 | E39: x
B40: 1.2.01.05 | C40: Linguiça Calabresa 400g Perdigao | D40: 7891515977511 | E40: x
B41: 1.2.01.05 | C41: Linguiça Calabresa 400g Seara | D41: 7894904009862 | E41: x
B42: 1.2.01.05 | C42: Linguiça Calabresa 400g Pamplona | D42: 7896716301271 | E42: x
...

Sheet M5
A2: QUESTIONÁRIO DE COLETA DE PREÇOS
A3: DATA: | B3: =IFERROR(Calendário!H8,"") -> 46274 | C3: ESTABELECIMENTO: | D3: =Calendário!C8 -> Mix Mateus
A4: SEMANA: | B4: =IFERROR(Calendário!E8,"") -> 1 | C4: PESQUISADOR: | D4: =IFERROR(IF(Calendário!I8=0,"",Calendário!I8),"") -> Carlos Eduardo
A5: HORA: | C5: CRÍTICA: | D5: =IFERROR(IF(Calendário!J8=0,"",Calendário!J8),"") -> Igor
A7: ITEM/PRODUTO | B7: CÓDIGO DO PRODUTO | C7: MARCAS DO PRODUTO | D7: CÓD. BARRAS PdH | E7: PREÇO
A8: Açúcar 1.1.05
A9: Açucar (1Kg)
B10: 1.1.05.01 | C10: Açucar Cristal Vida 1Kg | D10: 7898920795044 | E10: 2.99
B11: 1.1.05.01 | C11: Açucar Cristal Coceal 1Kg | D11: 7898292530038 | E11: x
B12: 1.1.05.01 | C12: Açúcar Cristal Vale Bahia 1Kg | D12: 7898968872011 | E12: x
B13: 1.1.05.01 | C13: Açucar Cristal Dona Mira 1Kg | D13: 7898964714070 | E13: 2.98
B14: 1.1.05.01 | C14: Açucar Cristal Baiano 1Kg | D14: 7898920795259 | E14: 2.95
A15: Arroz 1.2.03
A16: Arroz Parboilizado (1Kg)
B17: 1.2.03.01 | C17: Arroz Parboilizado Urbano 1Kg | D17: 7896038306053 | E17: 4.48
B18: 1.2.03.01 | C18: Arroz Parboilizado Tio João 1Kg | D18: 7893500018469 | E18: 4.88
B19: 1.2.03.01 | C19: Arroz Parboilizado Fazenda 1Kg | D19: 7896389600107 | E19: 3.98
B20: 1.2.03.01 | C20: Arroz Parboilizado Tia Maria 1Kg | D20: 609963230297 | E20: x
B21: 1.2.03.01 | C21: Arroz Parboilizado Camil 1Kg | D21: 7896006716112 | E21: 4.19
A22: Frutas 1.3.02
B23: 1.3.02.01 | C23: Banana da Prata (1 Kg) | D23: BANANA PRATA | E23: 6.79
B24: 1.3.02.02 | C24: Maça Nacional Vermelha (1 Kg) | D24: MAÇA NACIONAL | E24: x
A25: Café 1.1.03
A26: Café (250g)
B27: 1.1.03.01 | C27: Café Torrado e Moído Tradicional 250g Bahia a Vácuo | D27: 7898017920199 | E27: x
B28: 1.1.03.01 | C28: Café Torrado e Moído Tradicional 250g Pilão a Vácuo | D28: 7896089012637 | E28: 12.89
B29: 1.1.03.01 | C29: Café Torrado e Moído Tradicional 250g 3 Corações a Vácuo | D29: 7896005800362 | E29: 13.15
B30: 1.1.03.01 | C30: Café Torrado e Moído Tradicional 250g Mellita a Vácuo | D30: 7891021006071 | E30: 12.99
B31: 1.1.03.01 | C31: Café Torrado e Moído Tradicional 250g Maratá a Vácuo | D31: 7898286200039 | E31: 12.49
A32: Carnes, ovos e embutidos 1.2.01
B33: 1.2.01.01 | C33: Carne Acém (1 kg) | D33: CARNE ACÉM | E33: 33.9
B34: 1.2.01.02 | C34: Carne Alcatra (1 kg) | D34: CARNE ALCATRA | E34: x
B35: 1.2.01.03 | C35: Charque - Dianteira ou Ponta de Agulha (1Kg) | D35: CHARQUE | E35: x
B36: 1.2.01.04 | C36: Frango Inteiro Congelado (1 kg) | D36: FRANGO INTEIRO | E36: 7.45
B37: 1.2.01.06 | C37: Ovos Brancos (Unid.) | D37: OVOS BRANCOS | E37: x
A38: Linguiça Calabresa (400g)
B39: 1.2.01.05 | C39: Linguiça Calabresa 400g Sadia | D39: 7891515620981 | E39: x
B40: 1.2.01.05 | C40: Linguiça Calabresa 400g Perdigao | D40: 7891515977511 | E40: x
B41: 1.2.01.05 | C41: Linguiça Calabresa 400g Seara | D41: 7894904009862 | E41: 14.98
B42: 1.2.01.05 | C42: Linguiça Calabresa 400g Pamplona | D42: 7896716301271 | E42: x
...

Sheet M6
A2: QUESTIONÁRIO DE COLETA DE PREÇOS
A3: DATA: | B3: =IFERROR(Calendário!H9,"") -> 46274 | C3: ESTABELECIMENTO: | D3: =Calendário!C9 -> Mercado Eliene
A4: SEMANA: | B4: =IFERROR(Calendário!E9,"") -> 1 | C4: PESQUISADOR: | D4: =IFERROR(IF(Calendário!I9=0,"",Calendário!I9),"") -> Carlos Eduardo
A5: HORA: | C5: CRÍTICA: | D5: =IFERROR(IF(Calendário!J9=0,"",Calendário!J9),"") -> Igor
A7: ITEM/PRODUTO | B7: CÓDIGO DO PRODUTO | C7: MARCAS DO PRODUTO | D7: CÓD. BARRAS PdH | E7: PREÇO
A8: Açúcar 1.1.05
A9: Açucar (1Kg)
B10: 1.1.05.01 | C10: Açucar Cristal Vida 1Kg | D10: 7898920795044 | E10: x
B11: 1.1.05.01 | C11: Açucar Cristal Coceal 1Kg | D11: 7898292530038 | E11: 3.99
B12: 1.1.05.01 | C12: Açúcar Cristal Vale Bahia 1Kg | D12: 7898968872011 | E12: x
B13: 1.1.05.01 | C13: Açucar Cristal Dona Mira 1Kg | D13: 7898964714070 | E13: x
B14: 1.1.05.01 | C14: Açucar Cristal Baiano 1Kg | D14: 7898920795259 | E14: x
A15: Arroz 1.2.03
A16: Arroz Parboilizado (1Kg)
B17: 1.2.03.01 | C17: Arroz Parboilizado Urbano 1Kg | D17: 7896038306053 | E17: x
B18: 1.2.03.01 | C18: Arroz Parboilizado Tio João 1Kg | D18: 7893500018469 | E18: x
B19: 1.2.03.01 | C19: Arroz Parboilizado Fazenda 1Kg | D19: 7896389600107 | E19: x
B20: 1.2.03.01 | C20: Arroz Parboilizado Tia Maria 1Kg | D20: 609963230297 | E20: x
B21: 1.2.03.01 | C21: Arroz Parboilizado Camil 1Kg | D21: 7896006716112 | E21: x
A22: Frutas 1.3.02
B23: 1.3.02.01 | C23: Banana da Prata (1 Kg) | D23: BANANA PRATA | E23: x
B24: 1.3.02.02 | C24: Maça Nacional Vermelha (1 Kg) | D24: MAÇA NACIONAL | E24: x
A25: Café 1.1.03
A26: Café (250g)
B27: 1.1.03.01 | C27: Café Torrado e Moído Tradicional 250g Bahia a Vácuo | D27: 7898017920199 | E27: x
B28: 1.1.03.01 | C28: Café Torrado e Moído Tradicional 250g Pilão a Vácuo | D28: 7896089012637 | E28: x
B29: 1.1.03.01 | C29: Café Torrado e Moído Tradicional 250g 3 Corações a Vácuo | D29: 7896005800362 | E29: x
B30: 1.1.03.01 | C30: Café Torrado e Moído Tradicional 250g Mellita a Vácuo | D30: 7891021006071 | E30: x
B31: 1.1.03.01 | C31: Café Torrado e Moído Tradicional 250g Maratá a Vácuo | D31: 7898286200039 | E31: x
A32: Carnes, ovos e embutidos 1.2.01
B33: 1.2.01.01 | C33: Carne Acém (1 kg) | D33: CARNE ACÉM | E33: x
B34: 1.2.01.02 | C34: Carne Alcatra (1 kg) | D34: CARNE ALCATRA | E34: x
B35: 1.2.01.03 | C35: Charque - Dianteira ou Ponta de Agulha (1Kg) | D35: CHARQUE | E35: x
B36: 1.2.01.04 | C36: Frango Inteiro Congelado (1 kg) | D36: FRANGO INTEIRO | E36: x
B37: 1.2.01.06 | C37: Ovos Brancos (Unid.) | D37: OVOS BRANCOS | E37: x
A38: Linguiça Calabresa (400g)
B39: 1.2.01.05 | C39: Linguiça Calabresa 400g Sadia | D39: 7891515620981 | E39: x
B40: 1.2.01.05 | C40: Linguiça Calabresa 400g Perdigao | D40: 7891515977511 | E40: x
B41: 1.2.01.05 | C41: Linguiça Calabresa 400g Seara | D41: 7894904009862 | E41: x
B42: 1.2.01.05 | C42: Linguiça Calabresa 400g Pamplona | D42: 7896716301271 | E42: x
...

Sheet M7
A2: QUESTIONÁRIO DE COLETA DE PREÇOS
A3: DATA: | B3: =IFERROR(Calendário!H10,"") -> 46275 | C3: ESTABELECIMENTO: | D3: =Calendário!C10 -> Santo Antônio Supermercados
A4: SEMANA: | B4: =IFERROR(Calendário!E10,"") -> 1 | C4: PESQUISADOR: | D4: =IFERROR(IF(Calendário!I10=0,"",Calendário!I10),"") -> Igor
A5: HORA: | C5: CRÍTICA: | D5: =IFERROR(IF(Calendário!J10=0,"",Calendário!J10),"") -> Mécia
A7: ITEM/PRODUTO | B7: CÓDIGO DO PRODUTO | C7: MARCAS DO PRODUTO | D7: CÓD. BARRAS PdH | E7: PREÇO
A8: Açúcar 1.1.05
A9: Açucar (1Kg)
B10: 1.1.05.01 | C10: Açucar Cristal Vida 1Kg | D10: 7898920795044 | E10: x
B11: 1.1.05.01 | C11: Açucar Cristal Coceal 1Kg | D11: 7898292530038 | E11: 4.45
B12: 1.1.05.01 | C12: Açúcar Cristal Vale Bahia 1Kg | D12: 7898968872011 | E12: x
B13: 1.1.05.01 | C13: Açucar Cristal Dona Mira 1Kg | D13: 7898964714070 | E13: x
B14: 1.1.05.01 | C14: Açucar Cristal Baiano 1Kg | D14: 7898920795259 | E14: x
A15: Arroz 1.2.03
A16: Arroz Parboilizado (1Kg)
B17: 1.2.03.01 | C17: Arroz Parboilizado Urbano 1Kg | D17: 7896038306053 | E17: 4.99
B18: 1.2.03.01 | C18: Arroz Parboilizado Tio João 1Kg | D18: 7893500018469 | E18: 6.2
B19: 1.2.03.01 | C19: Arroz Parboilizado Fazenda 1Kg | D19: 7896389600107 | E19: 4.4
B20: 1.2.03.01 | C20: Arroz Parboilizado Tia Maria 1Kg | D20: 609963230297 | E20: 4.29
B21: 1.2.03.01 | C21: Arroz Parboilizado Camil 1Kg | D21: 7896006716112 | E21: x
A22: Frutas 1.3.02
B23: 1.3.02.01 | C23: Banana da Prata (1 Kg) | D23: BANANA PRATA | E23: 8.99
B24: 1.3.02.02 | C24: Maça Nacional Vermelha (1 Kg) | D24: MAÇA NACIONAL | E24: 9.98
A25: Café 1.1.03
A26: Café (250g)
B27: 1.1.03.01 | C27: Café Torrado e Moído Tradicional 250g Bahia a Vácuo | D27: 7898017920199 | E27: 16.95
B28: 1.1.03.01 | C28: Café Torrado e Moído Tradicional 250g Pilão a Vácuo | D28: 7896089012637 | E28: x
B29: 1.1.03.01 | C29: Café Torrado e Moído Tradicional 250g 3 Corações a Vácuo | D29: 7896005800362 | E29: 17.99
B30: 1.1.03.01 | C30: Café Torrado e Moído Tradicional 250g Mellita a Vácuo | D30: 7891021006071 | E30: 17.9
B31: 1.1.03.01 | C31: Café Torrado e Moído Tradicional 250g Maratá a Vácuo | D31: 7898286200039 | E31: 14.9
A32: Carnes, ovos e embutidos 1.2.01
B33: 1.2.01.01 | C33: Carne Acém (1 kg) | D33: CARNE ACÉM | E33: x
B34: 1.2.01.02 | C34: Carne Alcatra (1 kg) | D34: CARNE ALCATRA | E34: 37.9
B35: 1.2.01.03 | C35: Charque - Dianteira ou Ponta de Agulha (1Kg) | D35: CHARQUE | E35: 54.9
B36: 1.2.01.04 | C36: Frango Inteiro Congelado (1 kg) | D36: FRANGO INTEIRO | E36: x
B37: 1.2.01.06 | C37: Ovos Brancos (Unid.) | D37: OVOS BRANCOS | E37: x
A38: Linguiça Calabresa (400g)
B39: 1.2.01.05 | C39: Linguiça Calabresa 400g Sadia | D39: 7891515620981 | E39: 12.9
B40: 1.2.01.05 | C40: Linguiça Calabresa 400g Perdigao | D40: 7891515977511 | E40: 16.29
B41: 1.2.01.05 | C41: Linguiça Calabresa 400g Seara | D41: 7894904009862 | E41: 16.49
B42: 1.2.01.05 | C42: Linguiça Calabresa 400g Pamplona | D42: 7896716301271 | E42: x
...

Sheet M8
A2: QUESTIONÁRIO DE COLETA DE PREÇOS
A3: DATA: | B3: =IFERROR(Calendário!H11,"") -> 46275 | C3: ESTABELECIMENTO: | D3: =Calendário!C11 -> Mercado Teixeira
A4: SEMANA: | B4: =IFERROR(Calendário!E11,"") -> 1 | C4: PESQUISADOR: | D4: =IFERROR(IF(Calendário!I11=0,"",Calendário!I11),"") -> Igor
A5: HORA: | C5: CRÍTICA: | D5: =IFERROR(IF(Calendário!J11=0,"",Calendário!J11),"") -> Mécia
A7: ITEM/PRODUTO | B7: CÓDIGO DO PRODUTO | C7: MARCAS DO PRODUTO | D7: CÓD. BARRAS PdH | E7: PREÇO
A8: Açúcar 1.1.05
A9: Açucar (1Kg)
B10: 1.1.05.01 | C10: Açucar Cristal Vida 1Kg | D10: 7898920795044 | E10: x
B11: 1.1.05.01 | C11: Açucar Cristal Coceal 1Kg | D11: 7898292530038 | E11: 4.29
B12: 1.1.05.01 | C12: Açúcar Cristal Vale Bahia 1Kg | D12: 7898968872011 | E12: x
B13: 1.1.05.01 | C13: Açucar Cristal Dona Mira 1Kg | D13: 7898964714070 | E13: x
B14: 1.1.05.01 | C14: Açucar Cristal Baiano 1Kg | D14: 7898920795259 | E14: x
A15: Arroz 1.2.03
A16: Arroz Parboilizado (1Kg)
B17: 1.2.03.01 | C17: Arroz Parboilizado Urbano 1Kg | D17: 7896038306053 | E17: x
B18: 1.2.03.01 | C18: Arroz Parboilizado Tio João 1Kg | D18: 7893500018469 | E18: x
B19: 1.2.03.01 | C19: Arroz Parboilizado Fazenda 1Kg | D19: 7896389600107 | E19: x
B20: 1.2.03.01 | C20: Arroz Parboilizado Tia Maria 1Kg | D20: 609963230297 | E20: x
B21: 1.2.03.01 | C21: Arroz Parboilizado Camil 1Kg | D21: 7896006716112 | E21: x
A22: Frutas 1.3.02
B23: 1.3.02.01 | C23: Banana da Prata (1 Kg) | D23: BANANA PRATA | E23: x
B24: 1.3.02.02 | C24: Maça Nacional Vermelha (1 Kg) | D24: MAÇA NACIONAL | E24: x
A25: Café 1.1.03
A26: Café (250g)
B27: 1.1.03.01 | C27: Café Torrado e Moído Tradicional 250g Bahia a Vácuo | D27: 7898017920199 | E27: x
B28: 1.1.03.01 | C28: Café Torrado e Moído Tradicional 250g Pilão a Vácuo | D28: 7896089012637 | E28: x
B29: 1.1.03.01 | C29: Café Torrado e Moído Tradicional 250g 3 Corações a Vácuo | D29: 7896005800362 | E29: x
B30: 1.1.03.01 | C30: Café Torrado e Moído Tradicional 250g Mellita a Vácuo | D30: 7891021006071 | E30: x
B31: 1.1.03.01 | C31: Café Torrado e Moído Tradicional 250g Maratá a Vácuo | D31: 7898286200039 | E31: x
A32: Carnes, ovos e embutidos 1.2.01
B33: 1.2.01.01 | C33: Carne Acém (1 kg) | D33: CARNE ACÉM | E33: x
B34: 1.2.01.02 | C34: Carne Alcatra (1 kg) | D34: CARNE ALCATRA | E34: x
B35: 1.2.01.03 | C35: Charque - Dianteira ou Ponta de Agulha (1Kg) | D35: CHARQUE | E35: 49.79
B36: 1.2.01.04 | C36: Frango Inteiro Congelado (1 kg) | D36: FRANGO INTEIRO | E36: x
B37: 1.2.01.06 | C37: Ovos Brancos (Unid.) | D37: OVOS BRANCOS | E37: 0.75
A38: Linguiça Calabresa (400g)
B39: 1.2.01.05 | C39: Linguiça Calabresa 400g Sadia | D39: 7891515620981 | E39: x
B40: 1.2.01.05 | C40: Linguiça Calabresa 400g Perdigao | D40: 7891515977511 | E40: x
B41: 1.2.01.05 | C41: Linguiça Calabresa 400g Seara | D41: 7894904009862 | E41: x
B42: 1.2.01.05 | C42: Linguiça Calabresa 400g Pamplona | D42: 7896716301271 | E42: x
...

Sheet M9
A2: QUESTIONÁRIO DE COLETA DE PREÇOS
A3: DATA: | B3: =IFERROR(Calendário!H12,"") -> 46276 | C3: ESTABELECIMENTO: | D3: =Calendário!C12 -> Supermercado Modelo
A4: SEMANA: | B4: =IFERROR(Calendário!E12,"") -> 1 | C4: PESQUISADOR: | D4: =IFERROR(IF(Calendário!I12=0,"",Calendário!I12),"") -> Mateus
A5: HORA: | C5: CRÍTICA: | D5: =IFERROR(IF(Calendário!J12=0,"",Calendário!J12),"") -> Darci
A7: ITEM/PRODUTO | B7: CÓDIGO DO PRODUTO | C7: MARCAS DO PRODUTO | D7: CÓD. BARRAS PdH | E7: PREÇO
A8: Açúcar 1.1.05
A9: Açucar (1Kg)
B10: 1.1.05.01 | C10: Açucar Cristal Vida 1Kg | D10: 7898920795044
B11: 1.1.05.01 | C11: Açucar Cristal Coceal 1Kg | D11: 7898292530038
B12: 1.1.05.01 | C12: Açúcar Cristal Vale Bahia 1Kg | D12: 7898968872011
B13: 1.1.05.01 | C13: Açucar Cristal Dona Mira 1Kg | D13: 7898964714070
B14: 1.1.05.01 | C14: Açucar Cristal Baiano 1Kg | D14: 7898920795259
A15: Arroz 1.2.03
A16: Arroz Parboilizado (1Kg)
B17: 1.2.03.01 | C17: Arroz Parboilizado Urbano 1Kg | D17: 7896038306053
B18: 1.2.03.01 | C18: Arroz Parboilizado Tio João 1Kg | D18: 7893500018469
B19: 1.2.03.01 | C19: Arroz Parboilizado Fazenda 1Kg | D19: 7896389600107
B20: 1.2.03.01 | C20: Arroz Parboilizado Tia Maria 1Kg | D20: 609963230297
B21: 1.2.03.01 | C21: Arroz Parboilizado Camil 1Kg | D21: 7896006716112
A22: Frutas 1.3.02
B23: 1.3.02.01 | C23: Banana da Prata (1 Kg) | D23: BANANA PRATA
B24: 1.3.02.02 | C24: Maça Nacional Vermelha (1 Kg) | D24: MAÇA NACIONAL
A25: Café 1.1.03
A26: Café (250g)
B27: 1.1.03.01 | C27: Café Torrado e Moído Tradicional 250g Bahia a Vácuo | D27: 7898017920199
B28: 1.1.03.01 | C28: Café Torrado e Moído Tradicional 250g Pilão a Vácuo | D28: 7896089012637
B29: 1.1.03.01 | C29: Café Torrado e Moído Tradicional 250g 3 Corações a Vácuo | D29: 7896005800362
B30: 1.1.03.01 | C30: Café Torrado e Moído Tradicional 250g Mellita a Vácuo | D30: 7891021006071
B31: 1.1.03.01 | C31: Café Torrado e Moído Tradicional 250g Maratá a Vácuo | D31: 7898286200039
A32: Carnes, ovos e embutidos 1.2.01
B33: 1.2.01.01 | C33: Carne Acém (1 kg) | D33: CARNE ACÉM
B34: 1.2.01.02 | C34: Carne Alcatra (1 kg) | D34: CARNE ALCATRA
B35: 1.2.01.03 | C35: Charque - Dianteira ou Ponta de Agulha (1Kg) | D35: CHARQUE
B36: 1.2.01.04 | C36: Frango Inteiro Congelado (1 kg) | D36: FRANGO INTEIRO
B37: 1.2.01.06 | C37: Ovos Brancos (Unid.) | D37: OVOS BRANCOS
A38: Linguiça Calabresa (400g)
B39: 1.2.01.05 | C39: Linguiça Calabresa 400g Sadia | D39: 7891515620981
B40: 1.2.01.05 | C40: Linguiça Calabresa 400g Perdigao | D40: 7891515977511
B41: 1.2.01.05 | C41: Linguiça Calabresa 400g Seara | D41: 7894904009862
B42: 1.2.01.05 | C42: Linguiça Calabresa 400g Pamplona | D42: 7896716301271
...

Sheet M10
A2: QUESTIONÁRIO DE COLETA DE PREÇOS
A3: DATA: | B3: =IFERROR(Calendário!H13,"") -> 46276 | C3: ESTABELECIMENTO: | D3: =Calendário!C13 -> Supermercado Esplendor
A4: SEMANA: | B4: =IFERROR(Calendário!E13,"") -> 1 | C4: PESQUISADOR: | D4: =IFERROR(IF(Calendário!I13=0,"",Calendário!I13),"") -> Mateus
A5: HORA: | C5: CRÍTICA: | D5: =IFERROR(IF(Calendário!J13=0,"",Calendário!J13),"") -> Darci
A7: ITEM/PRODUTO | B7: CÓDIGO DO PRODUTO | C7: MARCAS DO PRODUTO | D7: CÓD. BARRAS PdH | E7: PREÇO
A8: Açúcar 1.1.05
A9: Açucar (1Kg)
B10: 1.1.05.01 | C10: Açucar Cristal Vida 1Kg | D10: 7898920795044
B11: 1.1.05.01 | C11: Açucar Cristal Coceal 1Kg | D11: 7898292530038
B12: 1.1.05.01 | C12: Açúcar Cristal Vale Bahia 1Kg | D12: 7898968872011
B13: 1.1.05.01 | C13: Açucar Cristal Dona Mira 1Kg | D13: 7898964714070
B14: 1.1.05.01 | C14: Açucar Cristal Baiano 1Kg | D14: 7898920795259
A15: Arroz 1.2.03
A16: Arroz Parboilizado (1Kg)
B17: 1.2.03.01 | C17: Arroz Parboilizado Urbano 1Kg | D17: 7896038306053
B18: 1.2.03.01 | C18: Arroz Parboilizado Tio João 1Kg | D18: 7893500018469
B19: 1.2.03.01 | C19: Arroz Parboilizado Fazenda 1Kg | D19: 7896389600107
B20: 1.2.03.01 | C20: Arroz Parboilizado Tia Maria 1Kg | D20: 609963230297
B21: 1.2.03.01 | C21: Arroz Parboilizado Camil 1Kg | D21: 7896006716112
A22: Frutas 1.3.02
B23: 1.3.02.01 | C23: Banana da Prata (1 Kg) | D23: BANANA PRATA
B24: 1.3.02.02 | C24: Maça Nacional Vermelha (1 Kg) | D24: MAÇA NACIONAL
A25: Café 1.1.03
A26: Café (250g)
B27: 1.1.03.01 | C27: Café Torrado e Moído Tradicional 250g Bahia a Vácuo | D27: 7898017920199
B28: 1.1.03.01 | C28: Café Torrado e Moído Tradicional 250g Pilão a Vácuo | D28: 7896089012637
B29: 1.1.03.01 | C29: Café Torrado e Moído Tradicional 250g 3 Corações a Vácuo | D29: 7896005800362
B30: 1.1.03.01 | C30: Café Torrado e Moído Tradicional 250g Mellita a Vácuo | D30: 7891021006071
B31: 1.1.03.01 | C31: Café Torrado e Moído Tradicional 250g Maratá a Vácuo | D31: 7898286200039
A32: Carnes, ovos e embutidos 1.2.01
B33: 1.2.01.01 | C33: Carne Acém (1 kg) | D33: CARNE ACÉM
B34: 1.2.01.02 | C34: Carne Alcatra (1 kg) | D34: CARNE ALCATRA
B35: 1.2.01.03 | C35: Charque - Dianteira ou Ponta de Agulha (1Kg) | D35: CHARQUE
B36: 1.2.01.04 | C36: Frango Inteiro Congelado (1 kg) | D36: FRANGO INTEIRO
B37: 1.2.01.06 | C37: Ovos Brancos (Unid.) | D37: OVOS BRANCOS
A38: Linguiça Calabresa (400g)
B39: 1.2.01.05 | C39: Linguiça Calabresa 400g Sadia | D39: 7891515620981
B40: 1.2.01.05 | C40: Linguiça Calabresa 400g Perdigao | D40: 7891515977511
B41: 1.2.01.05 | C41: Linguiça Calabresa 400g Seara | D41: 7894904009862
B42: 1.2.01.05 | C42: Linguiça Calabresa 400g Pamplona | D42: 7896716301271
...

Sheet M11
A2: QUESTIONÁRIO DE COLETA DE PREÇOS
A3: DATA: | B3: =IFERROR(Calendário!H14,"") -> 46279 | C3: ESTABELECIMENTO: | D3: =Calendário!C14 -> Sendas Distribuidora S/A (Assaí Atacadista)
A4: SEMANA: | B4: =IFERROR(Calendário!E14,"") -> 2 | C4: PESQUISADOR: | D4: =IFERROR(IF(Calendário!I14=0,"",Calendário!I14),"") -> Mécia
A5: HORA: | C5: CRÍTICA: | D5: =IFERROR(IF(Calendário!J14=0,"",Calendário!J14),"") -> Mateus
A7: ITEM/PRODUTO | B7: CÓDIGO DO PRODUTO | C7: MARCAS DO PRODUTO | D7: CÓD. BARRAS PdH | E7: PREÇO
A8: Açúcar 1.1.05
A9: Açucar (1Kg)
B10: 1.1.05.01 | C10: Açucar Cristal Vida 1Kg | D10: 7898920795044
B11: 1.1.05.01 | C11: Açucar Cristal Coceal 1Kg | D11: 7898292530038
B12: 1.1.05.01 | C12: Açúcar Cristal Vale Bahia 1Kg | D12: 7898968872011
B13: 1.1.05.01 | C13: Açucar Cristal Dona Mira 1Kg | D13: 7898964714070
B14: 1.1.05.01 | C14: Açucar Cristal Baiano 1Kg | D14: 7898920795259
A15: Arroz 1.2.03
A16: Arroz Parboilizado (1Kg)
B17: 1.2.03.01 | C17: Arroz Parboilizado Urbano 1Kg | D17: 7896038306053
B18: 1.2.03.01 | C18: Arroz Parboilizado Tio João 1Kg | D18: 7893500018469
B19: 1.2.03.01 | C19: Arroz Parboilizado Fazenda 1Kg | D19: 7896389600107
B20: 1.2.03.01 | C20: Arroz Parboilizado Tia Maria 1Kg | D20: 609963230297
B21: 1.2.03.01 | C21: Arroz Parboilizado Camil 1Kg | D21: 7896006716112
A22: Frutas 1.3.02
B23: 1.3.02.01 | C23: Banana da Prata (1 Kg) | D23: BANANA PRATA
B24: 1.3.02.02 | C24: Maça Nacional Vermelha (1 Kg) | D24: MAÇA NACIONAL
A25: Café 1.1.03
A26: Café (250g)
B27: 1.1.03.01 | C27: Café Torrado e Moído Tradicional 250g Bahia a Vácuo | D27: 7898017920199
B28: 1.1.03.01 | C28: Café Torrado e Moído Tradicional 250g Pilão a Vácuo | D28: 7896089012637
B29: 1.1.03.01 | C29: Café Torrado e Moído Tradicional 250g 3 Corações a Vácuo | D29: 7896005800362
B30: 1.1.03.01 | C30: Café Torrado e Moído Tradicional 250g Mellita a Vácuo | D30: 7891021006071
B31: 1.1.03.01 | C31: Café Torrado e Moído Tradicional 250g Maratá a Vácuo | D31: 7898286200039
A32: Carnes, ovos e embutidos 1.2.01
B33: 1.2.01.01 | C33: Carne Acém (1 kg) | D33: CARNE ACÉM
B34: 1.2.01.02 | C34: Carne Alcatra (1 kg) | D34: CARNE ALCATRA
B35: 1.2.01.03 | C35: Charque - Dianteira ou Ponta de Agulha (1Kg) | D35: CHARQUE
B36: 1.2.01.04 | C36: Frango Inteiro Congelado (1 kg) | D36: FRANGO INTEIRO
B37: 1.2.01.06 | C37: Ovos Brancos (Unid.) | D37: OVOS BRANCOS
A38: Linguiça Calabresa (400g)
B39: 1.2.01.05 | C39: Linguiça Calabresa 400g Sadia | D39: 7891515620981
B40: 1.2.01.05 | C40: Linguiça Calabresa 400g Perdigao | D40: 7891515977511
B41: 1.2.01.05 | C41: Linguiça Calabresa 400g Seara | D41: 7894904009862
B42: 1.2.01.05 | C42: Linguiça Calabresa 400g Pamplona | D42: 7896716301271
...

Sheet M12
A2: QUESTIONÁRIO DE COLETA DE PREÇOS
A3: DATA: | B3: =IFERROR(Calendário!H15,"") -> 46279 | C3: ESTABELECIMENTO: | D3: =Calendário!C15 -> Supermercado Sampaio
A4: SEMANA: | B4: =IFERROR(Calendário!E15,"") -> 2 | C4: PESQUISADOR: | D4: =IFERROR(IF(Calendário!I15=0,"",Calendário!I15),"") -> Mécia
A5: HORA: | C5: CRÍTICA: | D5: =IFERROR(IF(Calendário!J15=0,"",Calendário!J15),"") -> Mateus
A7: ITEM/PRODUTO | B7: CÓDIGO DO PRODUTO | C7: MARCAS DO PRODUTO | D7: CÓD. BARRAS PdH | E7: PREÇO
A8: Açúcar 1.1.05
A9: Açucar (1Kg)
B10: 1.1.05.01 | C10: Açucar Cristal Vida 1Kg | D10: 7898920795044
B11: 1.1.05.01 | C11: Açucar Cristal Coceal 1Kg | D11: 7898292530038
B12: 1.1.05.01 | C12: Açúcar Cristal Vale Bahia 1Kg | D12: 7898968872011
B13: 1.1.05.01 | C13: Açucar Cristal Dona Mira 1Kg | D13: 7898964714070
B14: 1.1.05.01 | C14: Açucar Cristal Baiano 1Kg | D14: 7898920795259
A15: Arroz 1.2.03
A16: Arroz Parboilizado (1Kg)
B17: 1.2.03.01 | C17: Arroz Parboilizado Urbano 1Kg | D17: 7896038306053
B18: 1.2.03.01 | C18: Arroz Parboilizado Tio João 1Kg | D18: 7893500018469
B19: 1.2.03.01 | C19: Arroz Parboilizado Fazenda 1Kg | D19: 7896389600107
B20: 1.2.03.01 | C20: Arroz Parboilizado Tia Maria 1Kg | D20: 609963230297
B21: 1.2.03.01 | C21: Arroz Parboilizado Camil 1Kg | D21: 7896006716112
A22: Frutas 1.3.02
B23: 1.3.02.01 | C23: Banana da Prata (1 Kg) | D23: BANANA PRATA
B24: 1.3.02.02 | C24: Maça Nacional Vermelha (1 Kg) | D24: MAÇA NACIONAL
A25: Café 1.1.03
A26: Café (250g)
B27: 1.1.03.01 | C27: Café Torrado e Moído Tradicional 250g Bahia a Vácuo | D27: 7898017920199
B28: 1.1.03.01 | C28: Café Torrado e Moído Tradicional 250g Pilão a Vácuo | D28: 7896089012637
B29: 1.1.03.01 | C29: Café Torrado e Moído Tradicional 250g 3 Corações a Vácuo | D29: 7896005800362
B30: 1.1.03.01 | C30: Café Torrado e Moído Tradicional 250g Mellita a Vácuo | D30: 7891021006071
B31: 1.1.03.01 | C31: Café Torrado e Moído Tradicional 250g Maratá a Vácuo | D31: 7898286200039
A32: Carnes, ovos e embutidos 1.2.01
B33: 1.2.01.01 | C33: Carne Acém (1 kg) | D33: CARNE ACÉM
B34: 1.2.01.02 | C34: Carne Alcatra (1 kg) | D34: CARNE ALCATRA
B35: 1.2.01.03 | C35: Charque - Dianteira ou Ponta de Agulha (1Kg) | D35: CHARQUE
B36: 1.2.01.04 | C36: Frango Inteiro Congelado (1 kg) | D36: FRANGO INTEIRO
B37: 1.2.01.06 | C37: Ovos Brancos (Unid.) | D37: OVOS BRANCOS
A38: Linguiça Calabresa (400g)
B39: 1.2.01.05 | C39: Linguiça Calabresa 400g Sadia | D39: 7891515620981
B40: 1.2.01.05 | C40: Linguiça Calabresa 400g Perdigao | D40: 7891515977511
B41: 1.2.01.05 | C41: Linguiça Calabresa 400g Seara | D41: 7894904009862
B42: 1.2.01.05 | C42: Linguiça Calabresa 400g Pamplona | D42: 7896716301271
...

Sheet M13
A2: QUESTIONÁRIO DE COLETA DE PREÇOS
A3: DATA: | B3: =IFERROR(Calendário!H16,"") -> 46280 | C3: ESTABELECIMENTO: | D3: =Calendário!C16 -> Atacadão (Brumado)
A4: SEMANA: | B4: =IFERROR(Calendário!E16,"") -> 2 | C4: PESQUISADOR: | D4: =IFERROR(IF(Calendário!I16=0,"",Calendário!I16),"") -> Darci
A5: HORA: | B5: 0.88541667 | C5: CRÍTICA: | D5: =IFERROR(IF(Calendário!J16=0,"",Calendário!J16),"") -> Carlos Eduardo
A7: ITEM/PRODUTO | B7: CÓDIGO DO PRODUTO | C7: MARCAS DO PRODUTO | D7: CÓD. BARRAS PdH | E7: PREÇO
A8: Açúcar 1.1.05
A9: Açucar (1Kg)
B10: 1.1.05.01 | C10: Açucar Cristal Vida 1Kg | D10: 7898920795044 | E10: x
B11: 1.1.05.01 | C11: Açucar Cristal Coceal 1Kg | D11: 7898292530038 | E11: x
B12: 1.1.05.01 | C12: Açúcar Cristal Vale Bahia 1Kg | D12: 7898968872011 | E12: 3.19
B13: 1.1.05.01 | C13: Açucar Cristal Dona Mira 1Kg | D13: 7898964714070 | E13: x
B14: 1.1.05.01 | C14: Açucar Cristal Baiano 1Kg | D14: 7898920795259 | E14: x
A15: Arroz 1.2.03
A16: Arroz Parboilizado (1Kg)
B17: 1.2.03.01 | C17: Arroz Parboilizado Urbano 1Kg | D17: 7896038306053 | E17: 4.99
B18: 1.2.03.01 | C18: Arroz Parboilizado Tio João 1Kg | D18: 7893500018469 | E18: 5.39
B19: 1.2.03.01 | C19: Arroz Parboilizado Fazenda 1Kg | D19: 7896389600107 | E19: x
B20: 1.2.03.01 | C20: Arroz Parboilizado Tia Maria 1Kg | D20: 609963230297 | E20: x
B21: 1.2.03.01 | C21: Arroz Parboilizado Camil 1Kg | D21: 7896006716112 | E21: 5.29
A22: Frutas 1.3.02
B23: 1.3.02.01 | C23: Banana da Prata (1 Kg) | D23: BANANA PRATA | E23: 5.99
B24: 1.3.02.02 | C24: Maça Nacional Vermelha (1 Kg) | D24: MAÇA NACIONAL | E24: x
A25: Café 1.1.03
A26: Café (250g)
B27: 1.1.03.01 | C27: Café Torrado e Moído Tradicional 250g Bahia a Vácuo | D27: 7898017920199 | E27: 13,,5
B28: 1.1.03.01 | C28: Café Torrado e Moído Tradicional 250g Pilão a Vácuo | D28: 7896089012637 | E28: 15.9
B29: 1.1.03.01 | C29: Café Torrado e Moído Tradicional 250g 3 Corações a Vácuo | D29: 7896005800362 | E29: 14.5
B30: 1.1.03.01 | C30: Café Torrado e Moído Tradicional 250g Mellita a Vácuo | D30: 7891021006071 | E30: 15.5
B31: 1.1.03.01 | C31: Café Torrado e Moído Tradicional 250g Maratá a Vácuo | D31: 7898286200039 | E31: 15.5
A32: Carnes, ovos e embutidos 1.2.01
B33: 1.2.01.01 | C33: Carne Acém (1 kg) | D33: CARNE ACÉM | E33: x
B34: 1.2.01.02 | C34: Carne Alcatra (1 kg) | D34: CARNE ALCATRA | E34: x
B35: 1.2.01.03 | C35: Charque - Dianteira ou Ponta de Agulha (1Kg) | D35: CHARQUE | E35: 32.9
B36: 1.2.01.04 | C36: Frango Inteiro Congelado (1 kg) | D36: FRANGO INTEIRO | E36: x
B37: 1.2.01.06 | C37: Ovos Brancos (Unid.) | D37: OVOS BRANCOS | E37: x
A38: Linguiça Calabresa (400g)
B39: 1.2.01.05 | C39: Linguiça Calabresa 400g Sadia | D39: 7891515620981 | E39: 9.99
B40: 1.2.01.05 | C40: Linguiça Calabresa 400g Perdigao | D40: 7891515977511 | E40: 14.9
B41: 1.2.01.05 | C41: Linguiça Calabresa 400g Seara | D41: 7894904009862 | E41: x
B42: 1.2.01.05 | C42: Linguiça Calabresa 400g Pamplona | D42: 7896716301271 | E42: 13.89
...

Sheet M14
A2: QUESTIONÁRIO DE COLETA DE PREÇOS
A3: DATA: | B3: =IFERROR(Calendário!H17,"") -> 46280 | C3: ESTABELECIMENTO: | D3: =Calendário!C17 -> Supermercado Central Ipanema
A4: SEMANA: | B4: =IFERROR(Calendário!E17,"") -> 2 | C4: PESQUISADOR: | D4: =IFERROR(IF(Calendário!I17=0,"",Calendário!I17),"") -> Darci
A5: HORA: | B5: 0.88541667 | C5: CRÍTICA: | D5: =IFERROR(IF(Calendário!J17=0,"",Calendário!J17),"") -> Carlos Eduardo
A7: ITEM/PRODUTO | B7: CÓDIGO DO PRODUTO | C7: MARCAS DO PRODUTO | D7: CÓD. BARRAS PdH | E7: PREÇO
A8: Açúcar 1.1.05
A9: Açucar (1Kg)
B10: 1.1.05.01 | C10: Açucar Cristal Vida 1Kg | D10: 7898920795044 | E10: x
B11: 1.1.05.01 | C11: Açucar Cristal Coceal 1Kg | D11: 7898292530038 | E11: 4.39
B12: 1.1.05.01 | C12: Açúcar Cristal Vale Bahia 1Kg | D12: 7898968872011 | E12: x
B13: 1.1.05.01 | C13: Açucar Cristal Dona Mira 1Kg | D13: 7898964714070 | E13: x
B14: 1.1.05.01 | C14: Açucar Cristal Baiano 1Kg | D14: 7898920795259 | E14: x
A15: Arroz 1.2.03
A16: Arroz Parboilizado (1Kg)
B17: 1.2.03.01 | C17: Arroz Parboilizado Urbano 1Kg | D17: 7896038306053 | E17: x
B18: 1.2.03.01 | C18: Arroz Parboilizado Tio João 1Kg | D18: 7893500018469 | E18: x
B19: 1.2.03.01 | C19: Arroz Parboilizado Fazenda 1Kg | D19: 7896389600107 | E19: x
B20: 1.2.03.01 | C20: Arroz Parboilizado Tia Maria 1Kg | D20: 609963230297 | E20: x
B21: 1.2.03.01 | C21: Arroz Parboilizado Camil 1Kg | D21: 7896006716112 | E21: x
A22: Frutas 1.3.02
B23: 1.3.02.01 | C23: Banana da Prata (1 Kg) | D23: BANANA PRATA | E23: 6.75
B24: 1.3.02.02 | C24: Maça Nacional Vermelha (1 Kg) | D24: MAÇA NACIONAL | E24: x
A25: Café 1.1.03
A26: Café (250g)
B27: 1.1.03.01 | C27: Café Torrado e Moído Tradicional 250g Bahia a Vácuo | D27: 7898017920199 | E27: x
B28: 1.1.03.01 | C28: Café Torrado e Moído Tradicional 250g Pilão a Vácuo | D28: 7896089012637 | E28: x
B29: 1.1.03.01 | C29: Café Torrado e Moído Tradicional 250g 3 Corações a Vácuo | D29: 7896005800362 | E29: x
B30: 1.1.03.01 | C30: Café Torrado e Moído Tradicional 250g Mellita a Vácuo | D30: 7891021006071 | E30: x
B31: 1.1.03.01 | C31: Café Torrado e Moído Tradicional 250g Maratá a Vácuo | D31: 7898286200039 | E31: x
A32: Carnes, ovos e embutidos 1.2.01
B33: 1.2.01.01 | C33: Carne Acém (1 kg) | D33: CARNE ACÉM | E33: x
B34: 1.2.01.02 | C34: Carne Alcatra (1 kg) | D34: CARNE ALCATRA | E34: x
B35: 1.2.01.03 | C35: Charque - Dianteira ou Ponta de Agulha (1Kg) | D35: CHARQUE | E35: x
B36: 1.2.01.04 | C36: Frango Inteiro Congelado (1 kg) | D36: FRANGO INTEIRO | E36: x
B37: 1.2.01.06 | C37: Ovos Brancos (Unid.) | D37: OVOS BRANCOS | E37: x
A38: Linguiça Calabresa (400g)
B39: 1.2.01.05 | C39: Linguiça Calabresa 400g Sadia | D39: 7891515620981 | E39: x
B40: 1.2.01.05 | C40: Linguiça Calabresa 400g Perdigao | D40: 7891515977511 | E40: x
